<?xml version="1.0" ?>
<!-- =================================================================================== -->
<!-- |    This document was autogenerated by xacro from /usr/local/lib/python3.9/site-packages/robot_properties_solo/resources/xacro/solo8.urdf.xacro | -->
<!-- |    EDITING THIS FILE BY HAND IS NOT RECOMMENDED                                 | -->
<!-- =================================================================================== -->
<robot name="solo" xmlns:controller="http://playerstage.sourceforge.net/gazebo/xmlschema/#controller" xmlns:interface="http://playerstage.sourceforge.net/gazebo/xmlschema/#interface" xmlns:sensor="http://playerstage.sourceforge.net/gazebo/xmlschema/#sensor" xmlns:xacro="http://playerstage.sourceforge.net/gazebo/xmlschema/#interface">
  <!-- This file is based on: https://atlas.is.localnet/confluence/display/AMDW/Quadruped+URDF+Files -->
  <link name="base_link">
    <!-- BASE LINK INERTIAL -->
    <inertial>
      <origin rpy="0 0 0" xyz="0 0 0"/>
      <mass value="14.3315091"/>
      <!-- The base is extremely symmetrical. -->
      <inertia ixx="0.1" ixy="0.0" ixz="0.0" iyy="0.1" iyz="0.0" izz="0.1"/>
    </inertial>
    <!-- BASE LINK VISUAL -->
    <visual>
      <origin rpy="0 0 0" xyz="0 0 0"/>
      <geometry>
        <mesh filename="package://solo_control/meshes/stl/with_foot/solo_body.stl"/>
      </geometry>
      <material name="grey">
        <color rgba="0.8 0.8 0.8 1.0"/>
      </material>
    </visual>
    <!-- BASE LINK COLLISION -->
    <collision>
      <origin rpy="0 0 0" xyz="0 0 0"/>
      <geometry>
        <mesh filename="package://solo_control/meshes/stl/with_foot/solo_body.stl"/>
      </geometry>
      <material name="grey">
        <color rgba="0.8 0.8 0.8 1.0"/>
      </material>
    </collision>
    <!-- Bullet specific paramters -->
    <contact>
      <lateral_friction value="1.0"/>
      <restitution value="0.5"/>
    </contact>
  </link>
  <!-- END BASE LINK -->

  <!-- Joint between the base and the ${prefix} upper leg -->
  <joint name="FL_HFE" type="revolute">
    <parent link="base_link"/>
    <child link="FL_UPPER_LEG"/>
    <limit effort="100000" lower="-1000" upper="1000" velocity="100000"/>
    <!-- joints rotates around the y-axis -->
    <axis xyz="0 1 0"/>
    <origin rpy="0 0 0" xyz="0.19 0.1046 0"/>
    <!-- pybullet simulation parameters -->
    <dynamics damping="0.0" friction="0.0"/>
  </joint>

  <link name="FL_UPPER_LEG">
    <!-- Left upper leg inertia -->
    <inertial>
      <origin rpy="0 0 0" xyz="0.00001377 0.01935853 -0.07870700"/>
      <mass value="1.4853845"/>
      <inertia ixx="0.01" ixy="0.0" ixz="0.0" iyy="0.01" iyz="0.00004671" izz="0.01"/>
    </inertial>
    <!-- UPPER LEG LINK VISUAL -->
    <visual>
      <origin rpy="0 0 0" xyz="0 0 0"/>
      <geometry>
        <mesh filename="package://solo_control/meshes/stl/with_foot/solo_upper_leg_left_side.stl"/>
      </geometry>
      <material name="grey">
        <color rgba="0.8 0.8 0.8 1.0"/>
      </material>
    </visual>
    <!-- UPPER LEG LINK COLLISION -->
    <collision>
      <origin rpy="0 0 0" xyz="0 0 0"/>
      <geometry>
        <mesh filename="package://solo_control/meshes/stl/with_foot/solo_upper_leg_left_side.stl"/>
      </geometry>
      <material name="grey">
        <color rgba="0.8 0.8 0.8 1.0"/>
      </material>
    </collision>
    <!-- Bullet specific paramters -->
    <contact>
      <lateral_friction value="1.0"/>
      <restitution value="0.5"/>
    </contact>
  </link>
  <!-- END UPPER LEG LINK -->

  <!-- KFE: Joint between the upper leg and the lower leg -->
  <joint name="FL_KFE" type="revolute">
    <parent link="FL_UPPER_LEG"/>
    <child link="FL_LOWER_LEG"/>
    <limit effort="100000" lower="-1000" upper="1000" velocity="100000"/>
    <!-- joints rotates around the y-axis -->
    <axis xyz="0 1 0"/>
    <origin rpy="0 0 0" xyz="0 0.037450000000000004 -0.16"/>
    <!-- pybullet simulation parameters -->
    <dynamics damping="0.0" friction="0.0"/>
  </joint>

  <link name="FL_LOWER_LEG">
    <!-- Left lower leg inertia -->
    <inertial>
      <origin rpy="0 0 0" xyz="0.0 0.00787644 -0.08928215"/>
      <mass value="0.3070001"/>
      <inertia ixx="0.01" ixy="0.0" ixz="0.0" iyy="0.01" iyz="0.0" izz="0.01"/>
    </inertial>
    <!-- LOWER LEG LINK VISUAL -->
    <visual>
      <origin rpy="0 0 0" xyz="0 0 0"/>
      <geometry>
        <mesh filename="package://solo_control/meshes/stl/with_foot/solo_lower_leg_left_side.stl"/>
      </geometry>
      <material name="grey">
        <color rgba="0.8 0.8 0.8 1.0"/>
      </material>
    </visual>
    <!-- LOWER LEG LINK COLLISION -->
    <collision>
      <origin rpy="0 0 0" xyz="0 0 0"/>
      <geometry>
        <mesh filename="package://solo_control/meshes/stl/with_foot/solo_lower_leg_left_side.stl"/>
      </geometry>
      <material name="grey">
        <color rgba="0.8 0.8 0.8 1.0"/>
      </material>
    </collision>
    <!-- Bullet specific paramters -->
    <contact>
      <lateral_friction value="1.0"/>
      <restitution value="0.5"/>
    </contact>
  </link>
  <!-- END LOWER LEG LINK -->

  <!-- KFE: Joint between the upper leg and the lower leg -->
  <joint name="FL_ANKLE" type="fixed">
    <parent link="FL_LOWER_LEG"/>
    <child link="FL_FOOT"/>
    <origin rpy="0 0 0" xyz="0 0.008 -0.16"/>
    <!-- Limits (usefull?) -->
    <limit effort="100000" lower="-1000" upper="1000" velocity="100000"/>
    <!-- pybullet simulation parameters -->
    <dynamics damping="0.0" friction="0.0"/>
  </joint>

  <link name="FL_FOOT">
    <!-- FOOT INERTIAL -->
    <!-- This link is symmetrical left or right -->
    <inertial>
      <origin rpy="0 0 0" xyz="0 0 0.00035767"/>
      <mass value="0.0693606"/>
      <inertia ixx="0.01" ixy="0.0" ixz="0.0" iyy="0.01" iyz="0.0" izz="0.01"/>
    </inertial>
    <!-- FOOT VISUAL -->
    <visual>
      <origin rpy="0 0 0" xyz="0 0 0"/>
      <geometry>
        <mesh filename="package://solo_control/meshes/stl/with_foot/solo_foot.stl"/>
      </geometry>
      <material name="grey">
        <color rgba="0.8 0.8 0.8 1.0"/>
      </material>
    </visual>
    <!-- FOOT COLLISION -->
    <collision>
      <origin rpy="0 0 0" xyz="0 0 0"/>
      <geometry>
        <mesh filename="package://solo_control/meshes/stl/with_foot/solo_foot.stl"/>
      </geometry>
      <material name="grey">
        <color rgba="0.8 0.8 0.8 1.0"/>
      </material>
    </collision>
    <!-- Bullet specific paramters -->
    <contact>
      <lateral_friction value="1.0"/>
      <restitution value="0.5"/>
    </contact>
    <surface>
      <friction>
        <ode>
          <mu>5</mu>
          <mu2>5</mu2>
        </ode>
      </friction>
    </surface>
  </link>
  <!-- END LOWER LEG LINK -->

  <!-- Joint between the base and the ${prefix} upper leg -->
  <joint name="FR_HFE" type="revolute">
    <parent link="base_link"/>
    <child link="FR_UPPER_LEG"/>
    <limit effort="100000" lower="-1000" upper="1000" velocity="100000"/>
    <!-- joints rotates around the y-axis -->
    <axis xyz="0 1 0"/>
    <origin rpy="0 0 0" xyz="0.19 -0.1046 0"/>
    <!-- pybullet simulation parameters -->
    <dynamics damping="0.0" friction="0.0"/>
  </joint>

  <link name="FR_UPPER_LEG">
    <!-- Right upper leg inertia -->
    <inertial>
      <origin rpy="0 0 0" xyz="-0.00001377 -0.01935853 -0.07870700"/>
      <mass value="1.4853845"/>
      <inertia ixx="0.01" ixy="0.0" ixz="0.0" iyy="0.01" iyz="-0.0" izz="0.01"/>
    </inertial>
    <!-- UPPER LEG LINK VISUAL -->
    <visual>
      <origin rpy="0 0 0" xyz="0 0 0"/>
      <geometry>
        <mesh filename="package://solo_control/meshes/stl/with_foot/solo_upper_leg_right_side.stl"/>
      </geometry>
      <material name="grey">
        <color rgba="0.8 0.8 0.8 1.0"/>
      </material>
    </visual>
    <!-- UPPER LEG LINK COLLISION -->
    <collision>
      <origin rpy="0 0 0" xyz="0 0 0"/>
      <geometry>
        <mesh filename="package://solo_control/meshes/stl/with_foot/solo_upper_leg_right_side.stl"/>
      </geometry>
      <material name="grey">
        <color rgba="0.8 0.8 0.8 1.0"/>
      </material>
    </collision>
    <!-- Bullet specific paramters -->
    <contact>
      <lateral_friction value="1.0"/>
      <restitution value="0.5"/>
    </contact>
  </link>
  <!-- END UPPER LEG LINK -->

  <!-- KFE: Joint between the upper leg and the lower leg -->
  <joint name="FR_KFE" type="revolute">
    <parent link="FR_UPPER_LEG"/>
    <child link="FR_LOWER_LEG"/>
    <limit effort="100000" lower="-1000" upper="1000" velocity="100000"/>
    <!-- joints rotates around the y-axis -->
    <axis xyz="0 1 0"/>
    <origin rpy="0 0 0" xyz="0 -0.037450000000000004 -0.16"/>
    <!-- pybullet simulation parameters -->
    <dynamics damping="0.0" friction="0.0"/>
  </joint>

  <link name="FR_LOWER_LEG">
    <!-- Right lower leg inertia -->
    <inertial>
      <origin rpy="0 0 0" xyz="0.0 0.00787644 -0.08928215"/>
      <mass value="0.3070001"/>
      <inertia ixx="0.01" ixy="0.0" ixz="0.0" iyy="0.01" iyz="-0.0" izz="0.01"/>
    </inertial>
    <!-- LOWER LEG LINK VISUAL -->
    <visual>
      <origin rpy="0 0 0" xyz="0 0 0"/>
      <geometry>
        <mesh filename="package://solo_control/meshes/stl/with_foot/solo_lower_leg_right_side.stl"/>
      </geometry>
      <material name="grey">
        <color rgba="0.8 0.8 0.8 1.0"/>
      </material>
    </visual>
    <!-- LOWER LEG LINK COLLISION -->
    <collision>
      <origin rpy="0 0 0" xyz="0 0 0"/>
      <geometry>
        <mesh filename="package://solo_control/meshes/stl/with_foot/solo_lower_leg_right_side.stl"/>
      </geometry>
      <material name="grey">
        <color rgba="0.8 0.8 0.8 1.0"/>
      </material>
    </collision>
    <!-- Bullet specific paramters -->
    <contact>
      <lateral_friction value="1.0"/>
      <restitution value="0.5"/>
    </contact>
  </link>
  <!-- END LOWER LEG LINK -->

  <!-- KFE: Joint between the upper leg and the lower leg -->
  <joint name="FR_ANKLE" type="fixed">
    <parent link="FR_LOWER_LEG"/>
    <child link="FR_FOOT"/>
    <origin rpy="0 0 0" xyz="0 -0.008 -0.16"/>
    <!-- Limits (usefull?) -->
    <limit effort="100000" lower="-1000" upper="1000" velocity="100000"/>
    <!-- pybullet simulation parameters -->
    <dynamics damping="0.0" friction="0.0"/>
  </joint>

  <link name="FR_FOOT">
    <!-- FOOT INERTIAL -->
    <!-- This link is symmetrical left or right -->
    <inertial>
      <origin rpy="0 0 0" xyz="0 0 0.00035767"/>
      <mass value="0.0693606"/>
      <inertia ixx="0.01" ixy="0.0" ixz="0.0" iyy="0.01" iyz="0.0" izz="0.01"/>
    </inertial>
    <!-- FOOT VISUAL -->
    <visual>
      <origin rpy="0 0 0" xyz="0 0 0"/>
      <geometry>
        <mesh filename="package://solo_control/meshes/stl/with_foot/solo_foot.stl"/>
      </geometry>
      <material name="grey">
        <color rgba="0.8 0.8 0.8 1.0"/>
      </material>
    </visual>
    <!-- FOOT COLLISION -->
    <collision>
      <origin rpy="0 0 0" xyz="0 0 0"/>
      <geometry>
        <mesh filename="package://solo_control/meshes/stl/with_foot/solo_foot.stl"/>
      </geometry>
      <material name="grey">
        <color rgba="0.8 0.8 0.8 1.0"/>
      </material>
    </collision>
    <!-- Bullet specific paramters -->
    <contact>
      <lateral_friction value="1.0"/>
      <restitution value="0.5"/>
    </contact>
    <surface>
      <friction>
        <ode>
          <mu>5</mu>
          <mu2>5</mu2>
        </ode>
      </friction>
    </surface>
  </link>
  <!-- END LOWER LEG LINK -->

  <!-- Joint between the base and the ${prefix} upper leg -->
  <joint name="HL_HFE" type="revolute">
    <parent link="base_link"/>
    <child link="HL_UPPER_LEG"/>
    <limit effort="100000" lower="-1000" upper="1000" velocity="100000"/>
    <!-- joints rotates around the y-axis -->
    <axis xyz="0 1 0"/>
    <origin rpy="0 0 0" xyz="-0.19 0.1046 0"/>
    <!-- pybullet simulation parameters -->
    <dynamics damping="0.0" friction="0.0"/>
  </joint>

  <link name="HL_UPPER_LEG">
    <!-- Left upper leg inertia -->
    <inertial>
      <origin rpy="0 0 0" xyz="0.00001377 0.01935853 -0.07870700"/>
      <mass value="1.4853845"/>
      <inertia ixx="0.01" ixy="0.0" ixz="0.0" iyy="0.01" iyz="0.00004671" izz="0.01"/>
    </inertial>
    <!-- UPPER LEG LINK VISUAL -->
    <visual>
      <origin rpy="0 0 0" xyz="0 0 0"/>
      <geometry>
        <mesh filename="package://solo_control/meshes/stl/with_foot/solo_upper_leg_left_side.stl"/>
      </geometry>
      <material name="grey">
        <color rgba="0.8 0.8 0.8 1.0"/>
      </material>
    </visual>
    <!-- UPPER LEG LINK COLLISION -->
    <collision>
      <origin rpy="0 0 0" xyz="0 0 0"/>
      <geometry>
        <mesh filename="package://solo_control/meshes/stl/with_foot/solo_upper_leg_left_side.stl"/>
      </geometry>
      <material name="grey">
        <color rgba="0.8 0.8 0.8 1.0"/>
      </material>
    </collision>
    <!-- Bullet specific paramters -->
    <contact>
      <lateral_friction value="1.0"/>
      <restitution value="0.5"/>
    </contact>
  </link>
  <!-- END UPPER LEG LINK -->

  <!-- KFE: Joint between the upper leg and the lower leg -->
  <joint name="HL_KFE" type="revolute">
    <parent link="HL_UPPER_LEG"/>
    <child link="HL_LOWER_LEG"/>
    <limit effort="100000" lower="-1000" upper="1000" velocity="100000"/>
    <!-- joints rotates around the y-axis -->
    <axis xyz="0 1 0"/>
    <origin rpy="0 0 0" xyz="0 0.037450000000000004 -0.16"/>
    <!-- pybullet simulation parameters -->
    <dynamics damping="0.0" friction="0.0"/>
  </joint>

  <link name="HL_LOWER_LEG">
    <!-- Left lower leg inertia -->
    <inertial>
      <origin rpy="0 0 0" xyz="0.0 0.00787644 -0.08928215"/>
      <mass value="0.3070001"/>
      <inertia ixx="0.01" ixy="0.0" ixz="0.0" iyy="0.01" iyz="0.0" izz="0.01"/>
    </inertial>
    <!-- LOWER LEG LINK VISUAL -->
    <visual>
      <origin rpy="0 0 0" xyz="0 0 0"/>
      <geometry>
        <mesh filename="package://solo_control/meshes/stl/with_foot/solo_lower_leg_left_side.stl"/>
      </geometry>
      <material name="grey">
        <color rgba="0.8 0.8 0.8 1.0"/>
      </material>
    </visual>
    <!-- LOWER LEG LINK COLLISION -->
    <collision>
      <origin rpy="0 0 0" xyz="0 0 0"/>
      <geometry>
        <mesh filename="package://solo_control/meshes/stl/with_foot/solo_lower_leg_left_side.stl"/>
      </geometry>
      <material name="grey">
        <color rgba="0.8 0.8 0.8 1.0"/>
      </material>
    </collision>
    <!-- Bullet specific paramters -->
    <contact>
      <lateral_friction value="1.0"/>
      <restitution value="0.5"/>
    </contact>
  </link>
  <!-- END LOWER LEG LINK -->

  <!-- KFE: Joint between the upper leg and the lower leg -->
  <joint name="HL_ANKLE" type="fixed">
    <parent link="HL_LOWER_LEG"/>
    <child link="HL_FOOT"/>
    <origin rpy="0 0 0" xyz="0 0.008 -0.16"/>
    <!-- Limits (usefull?) -->
    <limit effort="100000" lower="-1000" upper="1000" velocity="100000"/>
    <!-- pybullet simulation parameters -->
    <dynamics damping="0.0" friction="0.0"/>
  </joint>

  <link name="HL_FOOT">
    <!-- FOOT INERTIAL -->
    <!-- This link is symmetrical left or right -->
    <inertial>
      <origin rpy="0 0 0" xyz="0 0 0.00035767"/>
      <mass value="0.0693606"/>
      <inertia ixx="0.01" ixy="0.0" ixz="0.0" iyy="0.01" iyz="0.0" izz="0.01"/>
    </inertial>
    <!-- FOOT VISUAL -->
    <visual>
      <origin rpy="0 0 0" xyz="0 0 0"/>
      <geometry>
        <mesh filename="package://solo_control/meshes/stl/with_foot/solo_foot.stl"/>
      </geometry>
      <material name="grey">
        <color rgba="0.8 0.8 0.8 1.0"/>
      </material>
    </visual>
    <!-- FOOT COLLISION -->
    <collision>
      <origin rpy="0 0 0" xyz="0 0 0"/>
      <geometry>
        <mesh filename="package://solo_control/meshes/stl/with_foot/solo_foot.stl"/>
      </geometry>
      <material name="grey">
        <color rgba="0.8 0.8 0.8 1.0"/>
      </material>
    </collision>
    <!-- Bullet specific paramters -->
    <contact>
      <lateral_friction value="1.0"/>
      <restitution value="0.5"/>
    </contact>
    <surface>
      <friction>
        <ode>
          <mu>5</mu>
          <mu2>5</mu2>
        </ode>
      </friction>
    </surface>
  </link>
  <!-- END LOWER LEG LINK -->

  <!-- Joint between the base and the ${prefix} upper leg -->
  <joint name="HR_HFE" type="revolute">
    <parent link="base_link"/>
    <child link="HR_UPPER_LEG"/>
    <limit effort="100000" lower="-1000" upper="1000" velocity="100000"/>
    <!-- joints rotates around the y-axis -->
    <axis xyz="0 1 0"/>
    <origin rpy="0 0 0" xyz="-0.19 -0.1046 0"/>
    <!-- pybullet simulation parameters -->
    <dynamics damping="0.0" friction="0.0"/>
  </joint>

  <link name="HR_UPPER_LEG">
    <!-- Right upper leg inertia -->
    <inertial>
      <origin rpy="0 0 0" xyz="-0.00001377 -0.01935853 -0.07870700"/>
      <mass value="1.4853845"/>
      <inertia ixx="0.01" ixy="0.0" ixz="0.0" iyy="0.01" iyz="0.0" izz="0.01"/>
    </inertial>
    <!-- UPPER LEG LINK VISUAL -->
    <visual>
      <origin rpy="0 0 0" xyz="0 0 0"/>
      <geometry>
        <mesh filename="package://solo_control/meshes/stl/with_foot/solo_upper_leg_right_side.stl"/>
      </geometry>
      <material name="grey">
        <color rgba="0.8 0.8 0.8 1.0"/>
      </material>
    </visual>
    <!-- UPPER LEG LINK COLLISION -->
    <collision>
      <origin rpy="0 0 0" xyz="0 0 0"/>
      <geometry>
        <mesh filename="package://solo_control/meshes/stl/with_foot/solo_upper_leg_right_side.stl"/>
      </geometry>
      <material name="grey">
        <color rgba="0.8 0.8 0.8 1.0"/>
      </material>
    </collision>
    <!-- Bullet specific paramters -->
    <contact>
      <lateral_friction value="1.0"/>
      <restitution value="0.5"/>
    </contact>
  </link>
  <!-- END UPPER LEG LINK -->

  <!-- KFE: Joint between the upper leg and the lower leg -->
  <joint name="HR_KFE" type="revolute">
    <parent link="HR_UPPER_LEG"/>
    <child link="HR_LOWER_LEG"/>
    <limit effort="100000" lower="-1000" upper="1000" velocity="100000"/>
    <!-- joints rotates around the y-axis -->
    <axis xyz="0 1 0"/>
    <origin rpy="0 0 0" xyz="0 -0.037450000000000004 -0.16"/>
    <!-- pybullet simulation parameters -->
    <dynamics damping="0.0" friction="0.0"/>
  </joint>

  <link name="HR_LOWER_LEG">
    <!-- Right lower leg inertia -->
    <inertial>
      <origin rpy="0 0 0" xyz="0.0 0.00787644 -0.08928215"/>
      <mass value="0.3070001"/>
      <inertia ixx="0.01" ixy="0.0" ixz="0.0" iyy="0.01" iyz="0.0" izz="0.01"/>
    </inertial>
    <!-- LOWER LEG LINK VISUAL -->
    <visual>
      <origin rpy="0 0 0" xyz="0 0 0"/>
      <geometry>
        <mesh filename="package://solo_control/meshes/stl/with_foot/solo_lower_leg_right_side.stl"/>
      </geometry>
      <material name="grey">
        <color rgba="0.8 0.8 0.8 1.0"/>
      </material>
    </visual>
    <!-- LOWER LEG LINK COLLISION -->
    <collision>
      <origin rpy="0 0 0" xyz="0 0 0"/>
      <geometry>
        <mesh filename="package://solo_control/meshes/stl/with_foot/solo_lower_leg_right_side.stl"/>
      </geometry>
      <material name="grey">
        <color rgba="0.8 0.8 0.8 1.0"/>
      </material>
    </collision>
    <!-- Bullet specific paramters -->
    <contact>
      <lateral_friction value="1.0"/>
      <restitution value="0.5"/>
    </contact>
  </link>
  <!-- END LOWER LEG LINK -->

  <!-- KFE: Joint between the upper leg and the lower leg -->
  <joint name="HR_ANKLE" type="fixed">
    <parent link="HR_LOWER_LEG"/>
    <child link="HR_FOOT"/>
    <origin rpy="0 0 0" xyz="0 -0.008 -0.16"/>
    <!-- Limits (usefull?) -->
    <limit effort="100000" lower="-1000" upper="1000" velocity="100000"/>
    <!-- pybullet simulation parameters -->
    <dynamics damping="0.0" friction="0.0"/>
  </joint>

  <link name="HR_FOOT">
    <!-- FOOT INERTIAL -->
    <!-- This link is symmetrical left or right -->
    <inertial>
      <origin rpy="0 0 0" xyz="0 0 0.00035767"/>
      <mass value="0.0693606"/>
      <inertia ixx="0.01" ixy="0.0" ixz="0.0" iyy="0.01" iyz="0.0" izz="0.01"/>
    </inertial>
    <!-- FOOT VISUAL -->
    <visual>
      <origin rpy="0 0 0" xyz="0 0 0"/>
      <geometry>
        <mesh filename="package://solo_control/meshes/stl/with_foot/solo_foot.stl"/>
      </geometry>
      <material name="grey">
        <color rgba="0.8 0.8 0.8 1.0"/>
      </material>
    </visual>
    <!-- FOOT COLLISION -->
    <collision>
      <origin rpy="0 0 0" xyz="0 0 0"/>
      <geometry>
        <mesh filename="package://solo_control/meshes/stl/with_foot/solo_foot.stl"/>
      </geometry>
      <material name="grey">
        <color rgba="0.8 0.8 0.8 1.0"/>
      </material>
    </collision>
    <!-- Bullet specific paramters -->
    <contact>
      <lateral_friction value="1.0"/>
      <restitution value="0.5"/>
    </contact>
    <surface>
      <friction>
        <ode>
          <mu>5</mu>
          <mu2>5</mu2>
        </ode>
      </friction>
    </surface>
  </link>
  <!-- END LOWER LEG LINK -->

  <transmission name="transmission1">
    <type>transmission_interface/SimpleTransmission</type>
    <joint name="FL_HFE">
      <hardwareInterface>hardware_interface/PositionJointInterface</hardwareInterface>
    </joint>
    <actuator name="motor1">
      <mechanicalReduction>1</mechanicalReduction>
      <!--<hardwareInterface>hardware_interface/PositionJointInterface</hardwareInterface>-->
    </actuator>
  </transmission>

  <transmission name="transmission2">
    <type>transmission_interface/SimpleTransmission</type>
    <joint name="FL_KFE">
      <hardwareInterface>hardware_interface/PositionJointInterface</hardwareInterface>
    </joint>
    <actuator name="motor2">
      <mechanicalReduction>1</mechanicalReduction>
      <!--<hardwareInterface>hardware_interface/PositionJointInterface</hardwareInterface>-->
    </actuator>
  </transmission>

  <transmission name="transmission3">
    <type>transmission_interface/SimpleTransmission</type>
    <joint name="FR_HFE">
      <hardwareInterface>hardware_interface/PositionJointInterface</hardwareInterface>
    </joint>
    <actuator name="motor3">
      <mechanicalReduction>1</mechanicalReduction>
      <!--<hardwareInterface>hardware_interface/PositionJointInterface</hardwareInterface>-->
    </actuator>
  </transmission>

  <transmission name="transmission4">
    <type>transmission_interface/SimpleTransmission</type>
    <joint name="FR_KFE">
      <hardwareInterface>hardware_interface/PositionJointInterface</hardwareInterface>
    </joint>
    <actuator name="motor4">
      <mechanicalReduction>1</mechanicalReduction>
      <!--<hardwareInterface>hardware_interface/PositionJointInterface</hardwareInterface>-->
    </actuator>
  </transmission>

  <transmission name="transmission5">
    <type>transmission_interface/SimpleTransmission</type>
    <joint name="HL_HFE">
      <hardwareInterface>hardware_interface/PositionJointInterface</hardwareInterface>
    </joint>
    <actuator name="motor5">
      <mechanicalReduction>1</mechanicalReduction>
      <!--<hardwareInterface>hardware_interface/PositionJointInterface</hardwareInterface>-->
    </actuator>
  </transmission>

  <transmission name="transmission6">
    <type>transmission_interface/SimpleTransmission</type>
    <joint name="HL_KFE">
      <hardwareInterface>hardware_interface/PositionJointInterface</hardwareInterface>
    </joint>
    <actuator name="motor6">
      <mechanicalReduction>1</mechanicalReduction>
      <!--<hardwareInterface>hardware_interface/PositionJointInterface</hardwareInterface>-->
    </actuator>
  </transmission>

  <transmission name="transmission7">
    <type>transmission_interface/SimpleTransmission</type>
    <joint name="HR_HFE">
      <hardwareInterface>hardware_interface/PositionJointInterface</hardwareInterface>
    </joint>
    <actuator name="motor7">
      <mechanicalReduction>1</mechanicalReduction>
      <!--<hardwareInterface>hardware_interface/PositionJointInterface</hardwareInterface>-->
    </actuator>
  </transmission>

  <transmission name="transmission8">
    <type>transmission_interface/SimpleTransmission</type>
    <joint name="HR_KFE">
      <hardwareInterface>hardware_interface/PositionJointInterface</hardwareInterface>
    </joint>
    <actuator name="motor8">
      <mechanicalReduction>1</mechanicalReduction>
      <!--<hardwareInterface>hardware_interface/PositionJointInterface</hardwareInterface>-->
    </actuator>
  </transmission>

   <gazebo> 
    <plugin name="gazebo_ros_control" filename="libgazebo_ros_control.so">
      <legacyModeNS>false</legacyModeNS>
      <robotNamespace>/solo8</robotNamespace>
    </plugin>
   </gazebo> 

  <gazebo reference="FL_FOOT">
      <kp>1000.0</kp>
      <kd>0.1</kd>
      <mu1>0.8</mu1>
      <mu2>0.8</mu2>
      <maxVel>0.0</maxVel>
      <minDepth>0.001</minDepth>
      <material>Gazebo/Black </material>
    </gazebo>

  <gazebo reference="FR_FOOT">
      <kp>1000.0</kp>
      <kd>0.1</kd>
      <mu1>0.8</mu1>
      <mu2>0.8</mu2>
      <maxVel>0.0</maxVel>
      <minDepth>0.001</minDepth>
      <material>Gazebo/Black </material>
    </gazebo>

  <gazebo reference="HR_FOOT">
      <kp>1000.0</kp>
      <kd>0.1</kd>
      <mu1>0.8</mu1>
      <mu2>0.8</mu2>
      <maxVel>0.0</maxVel>
      <minDepth>0.001</minDepth>
      <material>Gazebo/Black </material>
    </gazebo>

  <gazebo reference="HL_FOOT">
      <kp>1000.0</kp>
      <kd>0.1</kd>
      <mu1>0.8</mu1>
      <mu2>0.8</mu2>
      <maxVel>0.0</maxVel>
      <minDepth>0.001</minDepth>
      <material>Gazebo/Black </material>
    </gazebo>

</robot>
